Workbook

Sheet WSC A
A1: Fecha | B1: Cuenta | C1: Producto | D1: Neto Agente | E1: Gross Agente | F1: Id_Off | G1: Id_manager | H1: MANAGER | I1: Id_oficial | J1: OFICIAL
F2: =VLOOKUP(B2,BASE!A:F,2,FALSE) -> #N/A | G2: =VLOOKUP(B2,BASE!A:F,3,FALSE) -> #N/A | H2: =VLOOKUP(B2,BASE!A:F,4,FALSE) -> #N/A | I2: =VLOOKUP(B2,BASE!A:F,6,FALSE) -> #N/A | J2: =VLOOKUP(B2,BASE!A:G,7,FALSE) -> #N/A
F3: =VLOOKUP(B3,BASE!A:F,2,FALSE) -> #N/A | G3: =VLOOKUP(B3,BASE!A:F,3,FALSE) -> #N/A | H3: =VLOOKUP(B3,BASE!A:F,4,FALSE) -> #N/A | I3: =VLOOKUP(B3,BASE!A:F,6,FALSE) -> #N/A | J3: =VLOOKUP(B3,BASE!A:G,7,FALSE) -> #N/A
F4: =VLOOKUP(B4,BASE!A:F,2,FALSE) -> #N/A | G4: =VLOOKUP(B4,BASE!A:F,3,FALSE) -> #N/A | H4: =VLOOKUP(B4,BASE!A:F,4,FALSE) -> #N/A | I4: =VLOOKUP(B4,BASE!A:F,6,FALSE) -> #N/A | J4: =VLOOKUP(B4,BASE!A:G,7,FALSE) -> #N/A
F5: =VLOOKUP(B5,BASE!A:F,2,FALSE) -> #N/A | G5: =VLOOKUP(B5,BASE!A:F,3,FALSE) -> #N/A | H5: =VLOOKUP(B5,BASE!A:F,4,FALSE) -> #N/A | I5: =VLOOKUP(B5,BASE!A:F,6,FALSE) -> #N/A | J5: =VLOOKUP(B5,BASE!A:G,7,FALSE) -> #N/A
F6: =VLOOKUP(B6,BASE!A:F,2,FALSE) -> #N/A | G6: =VLOOKUP(B6,BASE!A:F,3,FALSE) -> #N/A | H6: =VLOOKUP(B6,BASE!A:F,4,FALSE) -> #N/A | I6: =VLOOKUP(B6,BASE!A:F,6,FALSE) -> #N/A | J6: =VLOOKUP(B6,BASE!A:G,7,FALSE) -> #N/A
F7: =VLOOKUP(B7,BASE!A:F,2,FALSE) -> #N/A | G7: =VLOOKUP(B7,BASE!A:F,3,FALSE) -> #N/A | H7: =VLOOKUP(B7,BASE!A:F,4,FALSE) -> #N/A | I7: =VLOOKUP(B7,BASE!A:F,6,FALSE) -> #N/A | J7: =VLOOKUP(B7,BASE!A:G,7,FALSE) -> #N/A
F8: =VLOOKUP(B8,BASE!A:F,2,FALSE) -> #N/A | G8: =VLOOKUP(B8,BASE!A:F,3,FALSE) -> #N/A | H8: =VLOOKUP(B8,BASE!A:F,4,FALSE) -> #N/A | I8: =VLOOKUP(B8,BASE!A:F,6,FALSE) -> #N/A | J8: =VLOOKUP(B8,BASE!A:G,7,FALSE) -> #N/A
F9: =VLOOKUP(B9,BASE!A:F,2,FALSE) -> #N/A | G9: =VLOOKUP(B9,BASE!A:F,3,FALSE) -> #N/A | H9: =VLOOKUP(B9,BASE!A:F,4,FALSE) -> #N/A | I9: =VLOOKUP(B9,BASE!A:F,6,FALSE) -> #N/A | J9: =VLOOKUP(B9,BASE!A:G,7,FALSE) -> #N/A
F10: =VLOOKUP(B10,BASE!A:F,2,FALSE) -> #N/A | G10: =VLOOKUP(B10,BASE!A:F,3,FALSE) -> #N/A | H10: =VLOOKUP(B10,BASE!A:F,4,FALSE) -> #N/A | I10: =VLOOKUP(B10,BASE!A:F,6,FALSE) -> #N/A | J10: =VLOOKUP(B10,BASE!A:G,7,FALSE) -> #N/A
F11: =VLOOKUP(B11,BASE!A:F,2,FALSE) -> #N/A | G11: =VLOOKUP(B11,BASE!A:F,3,FALSE) -> #N/A | H11: =VLOOKUP(B11,BASE!A:F,4,FALSE) -> #N/A | I11: =VLOOKUP(B11,BASE!A:F,6,FALSE) -> #N/A | J11: =VLOOKUP(B11,BASE!A:G,7,FALSE) -> #N/A
F12: =VLOOKUP(B12,BASE!A:F,2,FALSE) -> #N/A | G12: =VLOOKUP(B12,BASE!A:F,3,FALSE) -> #N/A | H12: =VLOOKUP(B12,BASE!A:F,4,FALSE) -> #N/A | I12: =VLOOKUP(B12,BASE!A:F,6,FALSE) -> #N/A | J12: =VLOOKUP(B12,BASE!A:G,7,FALSE) -> #N/A
F13: =VLOOKUP(B13,BASE!A:F,2,FALSE) -> #N/A | G13: =VLOOKUP(B13,BASE!A:F,3,FALSE) -> #N/A | H13: =VLOOKUP(B13,BASE!A:F,4,FALSE) -> #N/A | I13: =VLOOKUP(B13,BASE!A:F,6,FALSE) -> #N/A | J13: =VLOOKUP(B13,BASE!A:G,7,FALSE) -> #N/A
... F6428: =VLOOKUP(B6428,BASE!A:F,2,FALSE) -> #N/A | G6428: =VLOOKUP(B6428,BASE!A:F,3,FALSE) -> #N/A | H6428: =VLOOKUP(B6428,BASE!A:F,4,FALSE) -> #N/A | I6428: =VLOOKUP(B6428,BASE!A:F,6,FALSE) -> #N/A | J6428: =VLOOKUP(B6428,BASE!A:G,7,FALSE) -> #N/A

Sheet WSC B
A1: Fecha | B1: Cuenta | C1: Producto | D1: Neto Agente | E1: Gross Agente | F1: Id_Off | G1: Id_manager | H1: MANAGER | I1: Id_oficial | J1: OFICIAL
F2: =VLOOKUP(B2,BASE!A:F,2,FALSE) -> #N/A | G2: =VLOOKUP(B2,BASE!A:F,3,FALSE) -> #N/A | H2: =VLOOKUP(B2,BASE!A:F,4,FALSE) -> #N/A | I2: =VLOOKUP(B2,BASE!A:F,6,FALSE) -> #N/A | J2: =VLOOKUP(B2,BASE!A:G,7,FALSE) -> #N/A
F3: =VLOOKUP(B3,BASE!A:F,2,FALSE) -> #N/A | G3: =VLOOKUP(B3,BASE!A:F,3,FALSE) -> #N/A | H3: =VLOOKUP(B3,BASE!A:F,4,FALSE) -> #N/A | I3: =VLOOKUP(B3,BASE!A:F,6,FALSE) -> #N/A | J3: =VLOOKUP(B3,BASE!A:G,7,FALSE) -> #N/A
F4: =VLOOKUP(B4,BASE!A:F,2,FALSE) -> #N/A | G4: =VLOOKUP(B4,BASE!A:F,3,FALSE) -> #N/A | H4: =VLOOKUP(B4,BASE!A:F,4,FALSE) -> #N/A | I4: =VLOOKUP(B4,BASE!A:F,6,FALSE) -> #N/A | J4: =VLOOKUP(B4,BASE!A:G,7,FALSE) -> #N/A
F5: =VLOOKUP(B5,BASE!A:F,2,FALSE) -> #N/A | G5: =VLOOKUP(B5,BASE!A:F,3,FALSE) -> #N/A | H5: =VLOOKUP(B5,BASE!A:F,4,FALSE) -> #N/A | I5: =VLOOKUP(B5,BASE!A:F,6,FALSE) -> #N/A | J5: =VLOOKUP(B5,BASE!A:G,7,FALSE) -> #N/A
F6: =VLOOKUP(B6,BASE!A:F,2,FALSE) -> #N/A | G6: =VLOOKUP(B6,BASE!A:F,3,FALSE) -> #N/A | H6: =VLOOKUP(B6,BASE!A:F,4,FALSE) -> #N/A | I6: =VLOOKUP(B6,BASE!A:F,6,FALSE) -> #N/A | J6: =VLOOKUP(B6,BASE!A:G,7,FALSE) -> #N/A
F7: =VLOOKUP(B7,BASE!A:F,2,FALSE) -> #N/A | G7: =VLOOKUP(B7,BASE!A:F,3,FALSE) -> #N/A | H7: =VLOOKUP(B7,BASE!A:F,4,FALSE) -> #N/A | I7: =VLOOKUP(B7,BASE!A:F,6,FALSE) -> #N/A | J7: =VLOOKUP(B7,BASE!A:G,7,FALSE) -> #N/A
F8: =VLOOKUP(B8,BASE!A:F,2,FALSE) -> #N/A | G8: =VLOOKUP(B8,BASE!A:F,3,FALSE) -> #N/A | H8: =VLOOKUP(B8,BASE!A:F,4,FALSE) -> #N/A | I8: =VLOOKUP(B8,BASE!A:F,6,FALSE) -> #N/A | J8: =VLOOKUP(B8,BASE!A:G,7,FALSE) -> #N/A
F9: =VLOOKUP(B9,BASE!A:F,2,FALSE) -> #N/A | G9: =VLOOKUP(B9,BASE!A:F,3,FALSE) -> #N/A | H9: =VLOOKUP(B9,BASE!A:F,4,FALSE) -> #N/A | I9: =VLOOKUP(B9,BASE!A:F,6,FALSE) -> #N/A | J9: =VLOOKUP(B9,BASE!A:G,7,FALSE) -> #N/A
F10: =VLOOKUP(B10,BASE!A:F,2,FALSE) -> #N/A | G10: =VLOOKUP(B10,BASE!A:F,3,FALSE) -> #N/A | H10: =VLOOKUP(B10,BASE!A:F,4,FALSE) -> #N/A | I10: =VLOOKUP(B10,BASE!A:F,6,FALSE) -> #N/A | J10: =VLOOKUP(B10,BASE!A:G,7,FALSE) -> #N/A
F11: =VLOOKUP(B11,BASE!A:F,2,FALSE) -> #N/A | G11: =VLOOKUP(B11,BASE!A:F,3,FALSE) -> #N/A | H11: =VLOOKUP(B11,BASE!A:F,4,FALSE) -> #N/A | I11: =VLOOKUP(B11,BASE!A:F,6,FALSE) -> #N/A | J11: =VLOOKUP(B11,BASE!A:G,7,FALSE) -> #N/A
F12: =VLOOKUP(B12,BASE!A:F,2,FALSE) -> #N/A | G12: =VLOOKUP(B12,BASE!A:F,3,FALSE) -> #N/A | H12: =VLOOKUP(B12,BASE!A:F,4,FALSE) -> #N/A | I12: =VLOOKUP(B12,BASE!A:F,6,FALSE) -> #N/A | J12: =VLOOKUP(B12,BASE!A:G,7,FALSE) -> #N/A
F13: =VLOOKUP(B13,BASE!A:F,2,FALSE) -> #N/A | G13: =VLOOKUP(B13,BASE!A:F,3,FALSE) -> #N/A | H13: =VLOOKUP(B13,BASE!A:F,4,FALSE) -> #N/A | I13: =VLOOKUP(B13,BASE!A:F,6,FALSE) -> #N/A | J13: =VLOOKUP(B13,BASE!A:G,7,FALSE) -> #N/A
... F101: =VLOOKUP(B101,BASE!A:F,2,FALSE) -> #N/A | G101: =VLOOKUP(B101,BASE!A:F,3,FALSE) -> #N/A | H101: =VLOOKUP(B101,BASE!A:F,4,FALSE) -> #N/A | I101: =VLOOKUP(B101,BASE!A:F,6,FALSE) -> #N/A | J101: =VLOOKUP(B101,BASE!A:G,7,FALSE) -> #N/A

Sheet INSIGNEO
A1: Fecha | B1: Cuenta | C1: Producto | D1: Neto Agente | E1: Gross Agente | F1: Id_Off | G1: Id_manager | H1: MANAGER | I1: Id_oficial | J1: OFICIAL
F2: =VLOOKUP(B2,BASE!A:F,2,FALSE) -> #N/A | G2: =VLOOKUP(B2,BASE!A:F,3,FALSE) -> #N/A | H2: =VLOOKUP(B2,BASE!A:F,4,FALSE) -> #N/A | I2: =VLOOKUP(B2,BASE!A:F,6,FALSE) -> #N/A | J2: =VLOOKUP(B2,BASE!A:G,7,FALSE) -> #N/A
F3: =VLOOKUP(B3,BASE!A:F,2,FALSE) -> #N/A | G3: =VLOOKUP(B3,BASE!A:F,3,FALSE) -> #N/A | H3: =VLOOKUP(B3,BASE!A:F,4,FALSE) -> #N/A | I3: =VLOOKUP(B3,BASE!A:F,6,FALSE) -> #N/A | J3: =VLOOKUP(B3,BASE!A:G,7,FALSE) -> #N/A
F4: =VLOOKUP(B4,BASE!A:F,2,FALSE) -> #N/A | G4: =VLOOKUP(B4,BASE!A:F,3,FALSE) -> #N/A | H4: =VLOOKUP(B4,BASE!A:F,4,FALSE) -> #N/A | I4: =VLOOKUP(B4,BASE!A:F,6,FALSE) -> #N/A | J4: =VLOOKUP(B4,BASE!A:G,7,FALSE) -> #N/A
F5: =VLOOKUP(B5,BASE!A:F,2,FALSE) -> #N/A | G5: =VLOOKUP(B5,BASE!A:F,3,FALSE) -> #N/A | H5: =VLOOKUP(B5,BASE!A:F,4,FALSE) -> #N/A | I5: =VLOOKUP(B5,BASE!A:F,6,FALSE) -> #N/A | J5: =VLOOKUP(B5,BASE!A:G,7,FALSE) -> #N/A
F6: =VLOOKUP(B6,BASE!A:F,2,FALSE) -> #N/A | G6: =VLOOKUP(B6,BASE!A:F,3,FALSE) -> #N/A | H6: =VLOOKUP(B6,BASE!A:F,4,FALSE) -> #N/A | I6: =VLOOKUP(B6,BASE!A:F,6,FALSE) -> #N/A | J6: =VLOOKUP(B6,BASE!A:G,7,FALSE) -> #N/A
F7: =VLOOKUP(B7,BASE!A:F,2,FALSE) -> #N/A | G7: =VLOOKUP(B7,BASE!A:F,3,FALSE) -> #N/A | H7: =VLOOKUP(B7,BASE!A:F,4,FALSE) -> #N/A | I7: =VLOOKUP(B7,BASE!A:F,6,FALSE) -> #N/A | J7: =VLOOKUP(B7,BASE!A:G,7,FALSE) -> #N/A
F8: =VLOOKUP(B8,BASE!A:F,2,FALSE) -> #N/A | G8: =VLOOKUP(B8,BASE!A:F,3,FALSE) -> #N/A | H8: =VLOOKUP(B8,BASE!A:F,4,FALSE) -> #N/A | I8: =VLOOKUP(B8,BASE!A:F,6,FALSE) -> #N/A | J8: =VLOOKUP(B8,BASE!A:G,7,FALSE) -> #N/A
F9: =VLOOKUP(B9,BASE!A:F,2,FALSE) -> #N/A | G9: =VLOOKUP(B9,BASE!A:F,3,FALSE) -> #N/A | H9: =VLOOKUP(B9,BASE!A:F,4,FALSE) -> #N/A | I9: =VLOOKUP(B9,BASE!A:F,6,FALSE) -> #N/A | J9: =VLOOKUP(B9,BASE!A:G,7,FALSE) -> #N/A
F10: =VLOOKUP(B10,BASE!A:F,2,FALSE) -> #N/A | G10: =VLOOKUP(B10,BASE!A:F,3,FALSE) -> #N/A | H10: =VLOOKUP(B10,BASE!A:F,4,FALSE) -> #N/A | I10: =VLOOKUP(B10,BASE!A:F,6,FALSE) -> #N/A | J10: =VLOOKUP(B10,BASE!A:G,7,FALSE) -> #N/A
F11: =VLOOKUP(B11,BASE!A:F,2,FALSE) -> #N/A | G11: =VLOOKUP(B11,BASE!A:F,3,FALSE) -> #N/A | H11: =VLOOKUP(B11,BASE!A:F,4,FALSE) -> #N/A | I11: =VLOOKUP(B11,BASE!A:F,6,FALSE) -> #N/A | J11: =VLOOKUP(B11,BASE!A:G,7,FALSE) -> #N/A
F12: =VLOOKUP(B12,BASE!A:F,2,FALSE) -> #N/A | G12: =VLOOKUP(B12,BASE!A:F,3,FALSE) -> #N/A | H12: =VLOOKUP(B12,BASE!A:F,4,FALSE) -> #N/A | I12: =VLOOKUP(B12,BASE!A:F,6,FALSE) -> #N/A | J12: =VLOOKUP(B12,BASE!A:G,7,FALSE) -> #N/A
F13: =VLOOKUP(B13,BASE!A:F,2,FALSE) -> #N/A | G13: =VLOOKUP(B13,BASE!A:F,3,FALSE) -> #N/A | H13: =VLOOKUP(B13,BASE!A:F,4,FALSE) -> #N/A | I13: =VLOOKUP(B13,BASE!A:F,6,FALSE) -> #N/A | J13: =VLOOKUP(B13,BASE!A:G,7,FALSE) -> #N/A
... F361: =VLOOKUP(B361,BASE!A:F,2,FALSE) -> #N/A | G361: =VLOOKUP(B361,BASE!A:F,3,FALSE) -> #N/A | H361: =VLOOKUP(B361,BASE!A:F,4,FALSE) -> #N/A | I361: =VLOOKUP(B361,BASE!A:F,6,FALSE) -> #N/A | J361: =VLOOKUP(B361,BASE!A:G,7,FALSE) -> #N/A

Sheet BASE
A1: CUENTA | B1: Id_Off | C1: Id_manager | D1: MANAGER | E1: NRO CN | F1: Id_oficial | G1: OFICIAL
A2: JQQ003272 | B2: 1 | C2: 25 | D2: =VLOOKUP(C2,manager!A:B,2) -> Goyheneix Esteban | E2: 9 | F2: 19 | G2: =VLOOKUP(F2,oficial!A:B,2) -> TOMAS VODANOVICH
A3: JQX006798 | B3: 2 | C3: 44 | D3: =VLOOKUP(C3,manager!A:B,2) -> Santiago Acuña | E3: 123 | F3: 96 | G3: =VLOOKUP(F3,oficial!A:B,2) -> TOMAS VODANOVICH
A4: JQX005907 | B4: 4 | C4: 7 | D4: =VLOOKUP(C4,manager!A:B,2) -> Travella Maximo | E4: 63 | F4: 96 | G4: =VLOOKUP(F4,oficial!A:B,2) -> TOMAS VODANOVICH
A5: JQX010238 | B5: 6 | C5: 13 | D5: =VLOOKUP(C5,manager!A:B,2) -> Linares Facundo | E5: 257 | F5: 15 | G5: =VLOOKUP(F5,oficial!A:B,2) -> TOBIAS MIRANDA
A6: JQX002086 | B6: 8 | C6: 49 | D6: =VLOOKUP(C6,manager!A:B,2) -> Carriquiri Ignacio | E6: 3 | F6: 96 | G6: =VLOOKUP(F6,oficial!A:B,2) -> TOMAS VODANOVICH
A7: JQX011541 | B7: 9 | C7: 49 | D7: =VLOOKUP(C7,manager!A:B,2) -> Carriquiri Ignacio | E7: 298 | F7: 96 | G7: =VLOOKUP(F7,oficial!A:B,2) -> TOMAS VODANOVICH
A8: 85997084 | B8: 10 | C8: 49 | D8: =VLOOKUP(C8,manager!A:B,2) -> Carriquiri Ignacio | E8: 179 | F8: 96 | G8: =VLOOKUP(F8,oficial!A:B,2) -> TOMAS VODANOVICH
A9: JQX009107 | B9: 12 | C9: 49 | D9: =VLOOKUP(C9,manager!A:B,2) -> Carriquiri Ignacio | E9: 204 | F9: 96 | G9: =VLOOKUP(F9,oficial!A:B,2) -> TOMAS VODANOVICH
A10: JQX005519 | B10: 14 | C10: 13 | D10: =VLOOKUP(C10,manager!A:B,2) -> Linares Facundo | E10: 15 | F10: 15 | G10: =VLOOKUP(F10,oficial!A:B,2) -> TOBIAS MIRANDA
A11: JQX009396 | B11: 15 | C11: 49 | D11: =VLOOKUP(C11,manager!A:B,2) -> Carriquiri Ignacio | E11: 213 | F11: 96 | G11: =VLOOKUP(F11,oficial!A:B,2) -> TOMAS VODANOVICH
A12: JQX001690 | B12: 16 | C12: 25 | D12: =VLOOKUP(C12,manager!A:B,2) -> Goyheneix Esteban | E12: 105 | F12: 19 | G12: =VLOOKUP(F12,oficial!A:B,2) -> TOMAS VODANOVICH
A13: JQX005352 | B13: 17 | C13: 14 | D13: =VLOOKUP(C13,manager!A:B,2) -> Mieres Lucas | E13: 22 | F13: 19 | G13: =VLOOKUP(F13,oficial!A:B,2) -> TOMAS VODANOVICH
A14: U2508525 | B14: 18 | C14: 25 | D14: =VLOOKUP(C14,manager!A:B,2) -> Goyheneix Esteban | E14: 134 | F14: 96 | G14: =VLOOKUP(F14,oficial!A:B,2) -> TOMAS VODANOVICH
A15: U2502661 | B15: 19 | C15: 25 | D15: =VLOOKUP(C15,manager!A:B,2) -> Goyheneix Esteban | E15: 144 | F15: 96 | G15: =VLOOKUP(F15,oficial!A:B,2) -> TOMAS VODANOVICH
A16: JQX003100 | B16: 20 | C16: 25 | D16: =VLOOKUP(C16,manager!A:B,2) -> Goyheneix Esteban | E16: 50 | F16: 96 | G16: =VLOOKUP(F16,oficial!A:B,2) -> TOMAS VODANOVICH
A17: JQX010782 | B17: 21 | C17: 25 | D17: =VLOOKUP(C17,manager!A:B,2) -> Goyheneix Esteban | E17: 279 | F17: 15 | G17: =VLOOKUP(F17,oficial!A:B,2) -> TOBIAS MIRANDA
A18: JQX004264 | B18: 22 | C18: 25 | D18: =VLOOKUP(C18,manager!A:B,2) -> Goyheneix Esteban | E18: 97 | F18: 19 | G18: =VLOOKUP(F18,oficial!A:B,2) -> TOMAS VODANOVICH
A19: JQX009289 | B19: 23 | C19: 49 | D19: =VLOOKUP(C19,manager!A:B,2) -> Carriquiri Ignacio | E19: 209 | F19: 96 | G19: =VLOOKUP(F19,oficial!A:B,2) -> TOMAS VODANOVICH
A20: JQX002185 | B20: 24 | C20: 25 | D20: =VLOOKUP(C20,manager!A:B,2) -> Goyheneix Esteban | E20: 75 | F20: 19 | G20: =VLOOKUP(F20,oficial!A:B,2) -> TOMAS VODANOVICH
... A157: JQX006962 | B157: 222 | C157: 25 | D157: =VLOOKUP(C157,manager!A:B,2) -> Goyheneix Esteban | E157: 136 | F157: 96 | G157: =VLOOKUP(F157,oficial!A:B,2) -> TOMAS VODANOVICH
A158: 24443734 | B158: 223 | C158: 49 | D158: =VLOOKUP(C158,manager!A:B,2) -> Carriquiri Ignacio | E158: 176 | F158: 96 | G158: =VLOOKUP(F158,oficial!A:B,2) -> TOMAS VODANOVICH
A159: JQX010493 | B159: 226 | C159: 13 | D159: =VLOOKUP(C159,manager!A:B,2) -> Linares Facundo | E159: 267 | F159: 15 | G159: =VLOOKUP(F159,oficial!A:B,2) -> TOBIAS MIRANDA
A160: JQX006814 | B160: 229 | C160: 49 | D160: =VLOOKUP(C160,manager!A:B,2) -> Carriquiri Ignacio | E160: 119 | F160: 96 | G160: =VLOOKUP(F160,oficial!A:B,2) -> TOMAS VODANOVICH
A161: JQX011590 | B161: 230 | C161: 49 | D161: =VLOOKUP(C161,manager!A:B,2) -> Carriquiri Ignacio | E161: 299 | F161: 96 | G161: =VLOOKUP(F161,oficial!A:B,2) -> TOMAS VODANOVICH
A162: JQX006145 | B162: 231 | C162: 25 | D162: =VLOOKUP(C162,manager!A:B,2) -> Goyheneix Esteban | E162: 196 | F162: 96 | G162: =VLOOKUP(F162,oficial!A:B,2) -> TOMAS VODANOVICH
A163: U2911955 | B163: 233 | C163: 49 | D163: =VLOOKUP(C163,manager!A:B,2) -> Carriquiri Ignacio | E163: 139 | F163: 96 | G163: =VLOOKUP(F163,oficial!A:B,2) -> TOMAS VODANOVICH
A164: JQX011913 | B164: 234 | C164: 13 | D164: =VLOOKUP(C164,manager!A:B,2) -> Linares Facundo | E164: 303 | F164: 15 | G164: =VLOOKUP(F164,oficial!A:B,2) -> TOBIAS MIRANDA
A165: JQX009024 | B165: 235 | C165: 117 | D165: =VLOOKUP(C165,manager!A:B,2) -> Nicanor Furlani | E165: 202 | F165: 10 | G165: =VLOOKUP(F165,oficial!A:B,2) -> NICANOR FURLANI
A166: JQX012242 | B166: 236 | C166: 124 | D166: =VLOOKUP(C166,manager!A:B,2) -> Tomas Pistone | E166: 312 | F166: 96 | G166: =VLOOKUP(F166,oficial!A:B,2) -> TOMAS VODANOVICH
A167: 82078314 | B167: 238 | C167: 49 | D167: =VLOOKUP(C167,manager!A:B,2) -> Carriquiri Ignacio | E167: 95 | F167: 96 | G167: =VLOOKUP(F167,oficial!A:B,2) -> TOMAS VODANOVICH
A168: JQX002557 | B168: 239 | C168: 25 | D168: =VLOOKUP(C168,manager!A:B,2) -> Goyheneix Esteban | E168: 114 | F168: 10 | G168: =VLOOKUP(F168,oficial!A:B,2) -> NICANOR FURLANI
A169: U9349624 | B169: 240 | C169: 14 | D169: =VLOOKUP(C169,manager!A:B,2) -> Mieres Lucas | E169: 142 | F169: 96 | G169: =VLOOKUP(F169,oficial!A:B,2) -> TOMAS VODANOVICH
A170: JQX010600 | B170: 241 | C170: 117 | D170: =VLOOKUP(C170,manager!A:B,2) -> Nicanor Furlani | E170: 271 | F170: 10 | G170: =VLOOKUP(F170,oficial!A:B,2) -> NICANOR FURLANI
A171: JQX010584 | B171: 242 | C171: 117 | D171: =VLOOKUP(C171,manager!A:B,2) -> Nicanor Furlani | E171: 272 | F171: 10 | G171: =VLOOKUP(F171,oficial!A:B,2) -> NICANOR FURLANI
A172: TE8015124 | B172: 243 | C172: 136 | D172: =VLOOKUP(C172,manager!A:B,2) -> Tomas Vodanovich | E172: 300 | F172: 19 | G172: =VLOOKUP(F172,oficial!A:B,2) -> TOMAS VODANOVICH
A173: U2608491 | B173: 244 | C173: 14 | D173: =VLOOKUP(C173,manager!A:B,2) -> Mieres Lucas | E173: 151 | F173: 96 | G173: =VLOOKUP(F173,oficial!A:B,2) -> TOMAS VODANOVICH
A174: JQX009925 | B174: 245 | C174: 104 | D174: =VLOOKUP(C174,manager!A:B,2) -> Britos Ramon | E174: 238 | F174: 96 | G174: =VLOOKUP(F174,oficial!A:B,2) -> TOMAS VODANOVICH
A175: JQX006442 | B175: 246 | C175: 25 | D175: =VLOOKUP(C175,manager!A:B,2) -> Goyheneix Esteban | E175: 111 | F175: 10 | G175: =VLOOKUP(F175,oficial!A:B,2) -> NICANOR FURLANI
A176: JQX011236 | B176: 247 | C176: 104 | D176: =VLOOKUP(C176,manager!A:B,2) -> Britos Ramon | E176: 291 | F176: 96 | G176: =VLOOKUP(F176,oficial!A:B,2) -> TOMAS VODANOVICH
...

Sheet oficial
A1: 2 | B1: JAVIER DE APELLANIZ
A2: 5 | B2: MIDDLE OFFICE
A3: 7 | B3: BRITOS RAMON
A4: 9 | B4: ALVANNY VILORIA
A5: 10 | B5: NICANOR FURLANI
A6: 11 | B6: OF A ASIGNAR
A7: 12 | B7: MESA
A8: 13 | B8: MARCELO ARIEL LIPOVETZKY
A9: 14 | B9: BRENDA MERINO
A10: 15 | B10: TOBIAS MIRANDA
A11: 16 | B11: JULIAN GONZALEZ
A12: 17 | B12: AGUSTIN FRERS
... A14: 19 | B14: TOMAS VODANOVICH

Sheet manager
A1: 1 | B1: Picolo Pablo
A2: 2 | B2: Family
A3: 3 | B3: Marotta Marcos
A4: 4 | B4: LANUSSE ANTONIO
A5: 5 | B5: Sicardi Jorge
A6: 6 | B6: NOGUER ESTEBAN
A7: 7 | B7: Travella Maximo
A8: 8 | B8: Montagna Alejandro
A9: 9 | B9: Grondona Tomas
A10: 10 | B10: Valenzuela Jorge
A11: 11 | B11: BRESCIA HORACIO
A12: 12 | B12: MORENO QUINTANA GONZALO
... A82: 151 | B82: Jaime Santamarina
